[13/Jun/2016 19:04:57] "GET / HTTP/1.1" 200 1538
[13/Jun/2016 19:04:58] "GET /static/css/blog.css HTTP/1.1" 304 0
[13/Jun/2016 19:05:03] "GET /post/2/ HTTP/1.1" 200 1072
[13/Jun/2016 19:05:07] "GET / HTTP/1.1" 200 1538
Not Found: /http:/www.baidu.com/cache/global/img/gs.gif
[14/Jun/2016 03:49:28] "GET http://www.baidu.com/cache/global/img/gs.gif HTTP/1.1" 404 1727
Not Found: /http:/www.baidu.com/
[14/Jun/2016 06:55:03] "GET http://www.baidu.com/ HTTP/1.1" 404 1658
[14/Jun/2016 10:55:04] "GET /post/new HTTP/1.1" 301 0
[14/Jun/2016 10:55:09] "GET /post/new/ HTTP/1.1" 200 1320
[14/Jun/2016 10:55:09] "GET /static/css/blog.css HTTP/1.1" 304 0
Not Found: /favicon.ico
[14/Jun/2016 10:55:09] "GET /favicon.ico HTTP/1.1" 404 2477
[14/Jun/2016 10:55:29] "POST /post/new/ HTTP/1.1" 200 1320
Performing system checks...

System check identified no issues (0 silenced).
June 13, 2016 - 19:04:48
Django version 1.9.6, using settings 'mysite.settings'
Starting development server at http://192.168.0.108:8000/
Quit the server with CONTROL-C.
Unhandled exception in thread started by <function check_errors.<locals>.wrapper at 0x75c234b0>
Traceback (most recent call last):
  File "/home/pi/django/myvenv/lib/python3.4/site-packages/django/utils/autoreload.py", line 226, in wrapper
    fn(*args, **kwargs)
  File "/home/pi/django/myvenv/lib/python3.4/site-packages/django/core/management/commands/runserver.py", line 116, in inner_run
    self.check(display_num_errors=True)
  File "/home/pi/django/myvenv/lib/python3.4/site-packages/django/core/management/base.py", line 426, in check
    include_deployment_checks=include_deployment_checks,
  File "/home/pi/django/myvenv/lib/python3.4/site-packages/django/core/checks/registry.py", line 75, in run_checks
    new_errors = check(app_configs=app_configs)
  File "/home/pi/django/myvenv/lib/python3.4/site-packages/django/core/checks/urls.py", line 13, in check_url_config
    return check_resolver(resolver)
  File "/home/pi/django/myvenv/lib/python3.4/site-packages/django/core/checks/urls.py", line 23, in check_resolver
    for pattern in resolver.url_patterns:
  File "/home/pi/django/myvenv/lib/python3.4/site-packages/django/utils/functional.py", line 33, in __get__
    res = instance.__dict__[self.name] = self.func(instance)
  File "/home/pi/django/myvenv/lib/python3.4/site-packages/django/core/urlresolvers.py", line 417, in url_patterns
    patterns = getattr(self.urlconf_module, "urlpatterns", self.urlconf_module)
  File "/home/pi/django/myvenv/lib/python3.4/site-packages/django/utils/functional.py", line 33, in __get__
    res = instance.__dict__[self.name] = self.func(instance)
  File "/home/pi/django/myvenv/lib/python3.4/site-packages/django/core/urlresolvers.py", line 410, in urlconf_module
    return import_module(self.urlconf_name)
  File "/home/pi/django/myvenv/lib/python3.4/importlib/__init__.py", line 109, in import_module
    return _bootstrap._gcd_import(name[level:], package, level)
  File "<frozen importlib._bootstrap>", line 2254, in _gcd_import
  File "<frozen importlib._bootstrap>", line 2237, in _find_and_load
  File "<frozen importlib._bootstrap>", line 2226, in _find_and_load_unlocked
  File "<frozen importlib._bootstrap>", line 1200, in _load_unlocked
  File "<frozen importlib._bootstrap>", line 1129, in _exec
  File "<frozen importlib._bootstrap>", line 1471, in exec_module
  File "<frozen importlib._bootstrap>", line 321, in _call_with_frames_removed
  File "/home/pi/django/mysite/urls.py", line 9, in <module>
    url(r'', include('blog.urls')),
  File "/home/pi/django/myvenv/lib/python3.4/site-packages/django/conf/urls/__init__.py", line 52, in include
    urlconf_module = import_module(urlconf_module)
  File "/home/pi/django/myvenv/lib/python3.4/importlib/__init__.py", line 109, in import_module
    return _bootstrap._gcd_import(name[level:], package, level)
  File "<frozen importlib._bootstrap>", line 2254, in _gcd_import
  File "<frozen importlib._bootstrap>", line 2237, in _find_and_load
  File "<frozen importlib._bootstrap>", line 2226, in _find_and_load_unlocked
  File "<frozen importlib._bootstrap>", line 1200, in _load_unlocked
  File "<frozen importlib._bootstrap>", line 1129, in _exec
  File "<frozen importlib._bootstrap>", line 1471, in exec_module
  File "<frozen importlib._bootstrap>", line 321, in _call_with_frames_removed
  File "/home/pi/django/blog/urls.py", line 2, in <module>
    from . import views
  File "/home/pi/django/blog/views.py", line 17
    from = PostForm(request.POST)
         ^
SyntaxError: invalid syntax
Performing system checks...

Unhandled exception in thread started by <function check_errors.<locals>.wrapper at 0x75bee4b0>
Traceback (most recent call last):
  File "/home/pi/django/myvenv/lib/python3.4/site-packages/django/utils/autoreload.py", line 226, in wrapper
    fn(*args, **kwargs)
  File "/home/pi/django/myvenv/lib/python3.4/site-packages/django/core/management/commands/runserver.py", line 116, in inner_run
    self.check(display_num_errors=True)
  File "/home/pi/django/myvenv/lib/python3.4/site-packages/django/core/management/base.py", line 426, in check
    include_deployment_checks=include_deployment_checks,
  File "/home/pi/django/myvenv/lib/python3.4/site-packages/django/core/checks/registry.py", line 75, in run_checks
    new_errors = check(app_configs=app_configs)
  File "/home/pi/django/myvenv/lib/python3.4/site-packages/django/core/checks/urls.py", line 13, in check_url_config
    return check_resolver(resolver)
  File "/home/pi/django/myvenv/lib/python3.4/site-packages/django/core/checks/urls.py", line 23, in check_resolver
    for pattern in resolver.url_patterns:
  File "/home/pi/django/myvenv/lib/python3.4/site-packages/django/utils/functional.py", line 33, in __get__
    res = instance.__dict__[self.name] = self.func(instance)
  File "/home/pi/django/myvenv/lib/python3.4/site-packages/django/core/urlresolvers.py", line 417, in url_patterns
    patterns = getattr(self.urlconf_module, "urlpatterns", self.urlconf_module)
  File "/home/pi/django/myvenv/lib/python3.4/site-packages/django/utils/functional.py", line 33, in __get__
    res = instance.__dict__[self.name] = self.func(instance)
  File "/home/pi/django/myvenv/lib/python3.4/site-packages/django/core/urlresolvers.py", line 410, in urlconf_module
    return import_module(self.urlconf_name)
  File "/home/pi/django/myvenv/lib/python3.4/importlib/__init__.py", line 109, in import_module
    return _bootstrap._gcd_import(name[level:], package, level)
  File "<frozen importlib._bootstrap>", line 2254, in _gcd_import
  File "<frozen importlib._bootstrap>", line 2237, in _find_and_load
  File "<frozen importlib._bootstrap>", line 2226, in _find_and_load_unlocked
  File "<frozen importlib._bootstrap>", line 1200, in _load_unlocked
  File "<frozen importlib._bootstrap>", line 1129, in _exec
  File "<frozen importlib._bootstrap>", line 1471, in exec_module
  File "<frozen importlib._bootstrap>", line 321, in _call_with_frames_removed
  File "/home/pi/django/mysite/urls.py", line 9, in <module>
    url(r'', include('blog.urls')),
  File "/home/pi/django/myvenv/lib/python3.4/site-packages/django/conf/urls/__init__.py", line 52, in include
    urlconf_module = import_module(urlconf_module)
  File "/home/pi/django/myvenv/lib/python3.4/importlib/__init__.py", line 109, in import_module
    return _bootstrap._gcd_import(name[level:], package, level)
  File "<frozen importlib._bootstrap>", line 2254, in _gcd_import
  File "<frozen importlib._bootstrap>", line 2237, in _find_and_load
  File "<frozen importlib._bootstrap>", line 2226, in _find_and_load_unlocked
  File "<frozen importlib._bootstrap>", line 1200, in _load_unlocked
  File "<frozen importlib._bootstrap>", line 1129, in _exec
  File "<frozen importlib._bootstrap>", line 1471, in exec_module
  File "<frozen importlib._bootstrap>", line 321, in _call_with_frames_removed
  File "/home/pi/django/blog/urls.py", line 2, in <module>
    from . import views
  File "/home/pi/django/blog/views.py", line 17
    from = PostForm(request.POST)
         ^
SyntaxError: invalid syntax
Performing system checks...

Traceback (most recent call last):
  File "manage.py", line 8, in <module>
    from django.core.management import execute_from_command_line
ImportError: No module named django.core.management
/home/pi/django/myvenv/lib/python3.4/site-packages/django/shortcuts.py:204: RemovedInDjango110Warning: Reversing by dotted path is deprecated (blog.views.post_detail).
  return urlresolvers.reverse(to, args=args, kwargs=kwargs)

[14/Jun/2016 11:14:01] "POST /post/new/ HTTP/1.1" 302 0
[14/Jun/2016 11:14:01] "GET /post/3/ HTTP/1.1" 200 1071
[14/Jun/2016 11:14:02] "GET /static/css/blog.css HTTP/1.1" 304 0
[14/Jun/2016 11:14:16] "GET /post/new/ HTTP/1.1" 200 1320
[14/Jun/2016 11:14:19] "POST /post/new/ HTTP/1.1" 200 1440
[14/Jun/2016 11:14:50] "POST /post/new/ HTTP/1.1" 200 1440
Performing system checks...

System check identified no issues (0 silenced).
June 14, 2016 - 11:13:50
Django version 1.9.6, using settings 'mysite.settings'
Starting development server at http://192.168.0.108:8000/
Quit the server with CONTROL-C.
Unhandled exception in thread started by <function check_errors.<locals>.wrapper at 0x75c5d4b0>
Traceback (most recent call last):
  File "/home/pi/django/myvenv/lib/python3.4/site-packages/django/utils/autoreload.py", line 226, in wrapper
    fn(*args, **kwargs)
  File "/home/pi/django/myvenv/lib/python3.4/site-packages/django/core/management/commands/runserver.py", line 116, in inner_run
    self.check(display_num_errors=True)
  File "/home/pi/django/myvenv/lib/python3.4/site-packages/django/core/management/base.py", line 426, in check
    include_deployment_checks=include_deployment_checks,
  File "/home/pi/django/myvenv/lib/python3.4/site-packages/django/core/checks/registry.py", line 75, in run_checks
    new_errors = check(app_configs=app_configs)
  File "/home/pi/django/myvenv/lib/python3.4/site-packages/django/core/checks/urls.py", line 13, in check_url_config
    return check_resolver(resolver)
  File "/home/pi/django/myvenv/lib/python3.4/site-packages/django/core/checks/urls.py", line 23, in check_resolver
    for pattern in resolver.url_patterns:
  File "/home/pi/django/myvenv/lib/python3.4/site-packages/django/utils/functional.py", line 33, in __get__
    res = instance.__dict__[self.name] = self.func(instance)
  File "/home/pi/django/myvenv/lib/python3.4/site-packages/django/core/urlresolvers.py", line 417, in url_patterns
    patterns = getattr(self.urlconf_module, "urlpatterns", self.urlconf_module)
  File "/home/pi/django/myvenv/lib/python3.4/site-packages/django/utils/functional.py", line 33, in __get__
    res = instance.__dict__[self.name] = self.func(instance)
  File "/home/pi/django/myvenv/lib/python3.4/site-packages/django/core/urlresolvers.py", line 410, in urlconf_module
    return import_module(self.urlconf_name)
  File "/home/pi/django/myvenv/lib/python3.4/importlib/__init__.py", line 109, in import_module
    return _bootstrap._gcd_import(name[level:], package, level)
  File "<frozen importlib._bootstrap>", line 2254, in _gcd_import
  File "<frozen importlib._bootstrap>", line 2237, in _find_and_load
  File "<frozen importlib._bootstrap>", line 2226, in _find_and_load_unlocked
  File "<frozen importlib._bootstrap>", line 1200, in _load_unlocked
  File "<frozen importlib._bootstrap>", line 1129, in _exec
  File "<frozen importlib._bootstrap>", line 1471, in exec_module
  File "<frozen importlib._bootstrap>", line 321, in _call_with_frames_removed
  File "/home/pi/django/mysite/urls.py", line 9, in <module>
    url(r'', include('blog.urls')),
  File "/home/pi/django/myvenv/lib/python3.4/site-packages/django/conf/urls/__init__.py", line 52, in include
    urlconf_module = import_module(urlconf_module)
  File "/home/pi/django/myvenv/lib/python3.4/importlib/__init__.py", line 109, in import_module
    return _bootstrap._gcd_import(name[level:], package, level)
  File "<frozen importlib._bootstrap>", line 2254, in _gcd_import
  File "<frozen importlib._bootstrap>", line 2237, in _find_and_load
  File "<frozen importlib._bootstrap>", line 2226, in _find_and_load_unlocked
  File "<frozen importlib._bootstrap>", line 1200, in _load_unlocked
  File "<frozen importlib._bootstrap>", line 1129, in _exec
  File "<frozen importlib._bootstrap>", line 1471, in exec_module
  File "<frozen importlib._bootstrap>", line 321, in _call_with_frames_removed
  File "/home/pi/django/blog/urls.py", line 5, in <module>
    url(r'post/(?P<pk>[0-9]+/edit/$', view.post_edit, name='post_edit'),
NameError: name 'view' is not defined
Performing system checks...

Unhandled exception in thread started by <function check_errors.<locals>.wrapper at 0x75b6e4b0>
Traceback (most recent call last):
  File "/home/pi/django/myvenv/lib/python3.4/site-packages/django/utils/autoreload.py", line 226, in wrapper
    fn(*args, **kwargs)
  File "/home/pi/django/myvenv/lib/python3.4/site-packages/django/core/management/commands/runserver.py", line 116, in inner_run
    self.check(display_num_errors=True)
  File "/home/pi/django/myvenv/lib/python3.4/site-packages/django/core/management/base.py", line 426, in check
    include_deployment_checks=include_deployment_checks,
  File "/home/pi/django/myvenv/lib/python3.4/site-packages/django/core/checks/registry.py", line 75, in run_checks
    new_errors = check(app_configs=app_configs)
  File "/home/pi/django/myvenv/lib/python3.4/site-packages/django/core/checks/urls.py", line 13, in check_url_config
    return check_resolver(resolver)
  File "/home/pi/django/myvenv/lib/python3.4/site-packages/django/core/checks/urls.py", line 23, in check_resolver
    for pattern in resolver.url_patterns:
  File "/home/pi/django/myvenv/lib/python3.4/site-packages/django/utils/functional.py", line 33, in __get__
    res = instance.__dict__[self.name] = self.func(instance)
  File "/home/pi/django/myvenv/lib/python3.4/site-packages/django/core/urlresolvers.py", line 417, in url_patterns
    patterns = getattr(self.urlconf_module, "urlpatterns", self.urlconf_module)
  File "/home/pi/django/myvenv/lib/python3.4/site-packages/django/utils/functional.py", line 33, in __get__
    res = instance.__dict__[self.name] = self.func(instance)
  File "/home/pi/django/myvenv/lib/python3.4/site-packages/django/core/urlresolvers.py", line 410, in urlconf_module
    return import_module(self.urlconf_name)
  File "/home/pi/django/myvenv/lib/python3.4/importlib/__init__.py", line 109, in import_module
    return _bootstrap._gcd_import(name[level:], package, level)
  File "<frozen importlib._bootstrap>", line 2254, in _gcd_import
  File "<frozen importlib._bootstrap>", line 2237, in _find_and_load
  File "<frozen importlib._bootstrap>", line 2226, in _find_and_load_unlocked
  File "<frozen importlib._bootstrap>", line 1200, in _load_unlocked
  File "<frozen importlib._bootstrap>", line 1129, in _exec
  File "<frozen importlib._bootstrap>", line 1471, in exec_module
  File "<frozen importlib._bootstrap>", line 321, in _call_with_frames_removed
  File "/home/pi/django/mysite/urls.py", line 9, in <module>
    url(r'', include('blog.urls')),
  File "/home/pi/django/myvenv/lib/python3.4/site-packages/django/conf/urls/__init__.py", line 52, in include
    urlconf_module = import_module(urlconf_module)
  File "/home/pi/django/myvenv/lib/python3.4/importlib/__init__.py", line 109, in import_module
    return _bootstrap._gcd_import(name[level:], package, level)
  File "<frozen importlib._bootstrap>", line 2254, in _gcd_import
  File "<frozen importlib._bootstrap>", line 2237, in _find_and_load
  File "<frozen importlib._bootstrap>", line 2226, in _find_and_load_unlocked
  File "<frozen importlib._bootstrap>", line 1200, in _load_unlocked
  File "<frozen importlib._bootstrap>", line 1129, in _exec
  File "<frozen importlib._bootstrap>", line 1471, in exec_module
  File "<frozen importlib._bootstrap>", line 321, in _call_with_frames_removed
  File "/home/pi/django/blog/urls.py", line 2, in <module>
    from . import views
  File "/home/pi/django/blog/views.py", line 30
    if
     ^
SyntaxError: invalid syntax
Performing system checks...

Unhandled exception in thread started by <function check_errors.<locals>.wrapper at 0x75c0f4b0>
Traceback (most recent call last):
  File "/home/pi/django/myvenv/lib/python3.4/site-packages/django/utils/autoreload.py", line 226, in wrapper
    fn(*args, **kwargs)
  File "/home/pi/django/myvenv/lib/python3.4/site-packages/django/core/management/commands/runserver.py", line 116, in inner_run
    self.check(display_num_errors=True)
  File "/home/pi/django/myvenv/lib/python3.4/site-packages/django/core/management/base.py", line 426, in check
    include_deployment_checks=include_deployment_checks,
  File "/home/pi/django/myvenv/lib/python3.4/site-packages/django/core/checks/registry.py", line 75, in run_checks
    new_errors = check(app_configs=app_configs)
  File "/home/pi/django/myvenv/lib/python3.4/site-packages/django/core/checks/urls.py", line 13, in check_url_config
    return check_resolver(resolver)
  File "/home/pi/django/myvenv/lib/python3.4/site-packages/django/core/checks/urls.py", line 23, in check_resolver
    for pattern in resolver.url_patterns:
  File "/home/pi/django/myvenv/lib/python3.4/site-packages/django/utils/functional.py", line 33, in __get__
    res = instance.__dict__[self.name] = self.func(instance)
  File "/home/pi/django/myvenv/lib/python3.4/site-packages/django/core/urlresolvers.py", line 417, in url_patterns
    patterns = getattr(self.urlconf_module, "urlpatterns", self.urlconf_module)
  File "/home/pi/django/myvenv/lib/python3.4/site-packages/django/utils/functional.py", line 33, in __get__
    res = instance.__dict__[self.name] = self.func(instance)
  File "/home/pi/django/myvenv/lib/python3.4/site-packages/django/core/urlresolvers.py", line 410, in urlconf_module
    return import_module(self.urlconf_name)
  File "/home/pi/django/myvenv/lib/python3.4/importlib/__init__.py", line 109, in import_module
    return _bootstrap._gcd_import(name[level:], package, level)
  File "<frozen importlib._bootstrap>", line 2254, in _gcd_import
  File "<frozen importlib._bootstrap>", line 2237, in _find_and_load
  File "<frozen importlib._bootstrap>", line 2226, in _find_and_load_unlocked
  File "<frozen importlib._bootstrap>", line 1200, in _load_unlocked
  File "<frozen importlib._bootstrap>", line 1129, in _exec
  File "<frozen importlib._bootstrap>", line 1471, in exec_module
  File "<frozen importlib._bootstrap>", line 321, in _call_with_frames_removed
  File "/home/pi/django/mysite/urls.py", line 9, in <module>
    url(r'', include('blog.urls')),
  File "/home/pi/django/myvenv/lib/python3.4/site-packages/django/conf/urls/__init__.py", line 52, in include
    urlconf_module = import_module(urlconf_module)
  File "/home/pi/django/myvenv/lib/python3.4/importlib/__init__.py", line 109, in import_module
    return _bootstrap._gcd_import(name[level:], package, level)
  File "<frozen importlib._bootstrap>", line 2254, in _gcd_import
  File "<frozen importlib._bootstrap>", line 2237, in _find_and_load
  File "<frozen importlib._bootstrap>", line 2226, in _find_and_load_unlocked
  File "<frozen importlib._bootstrap>", line 1200, in _load_unlocked
  File "<frozen importlib._bootstrap>", line 1129, in _exec
  File "<frozen importlib._bootstrap>", line 1471, in exec_module
  File "<frozen importlib._bootstrap>", line 321, in _call_with_frames_removed
  File "/home/pi/django/blog/urls.py", line 5, in <module>
    url(r'post/(?P<pk>[0-9]+/edit/$', view.post_edit, name='post_edit'),
NameError: name 'view' is not defined
Performing system checks...

[14/Jun/2016 11:36:18] "GET / HTTP/1.1" 200 1866
[14/Jun/2016 11:36:18] "GET /static/css/blog.css HTTP/1.1" 304 0
[14/Jun/2016 11:36:24] "GET /post/2/ HTTP/1.1" 200 1181
[14/Jun/2016 11:36:26] "GET /post/2/edit/ HTTP/1.1" 200 1352
Internal Server Error: /post/2/edit/
Traceback (most recent call last):
  File "/home/pi/django/myvenv/lib/python3.4/site-packages/django/core/handlers/base.py", line 149, in get_response
    response = self.process_exception_by_middleware(e, request)
  File "/home/pi/django/myvenv/lib/python3.4/site-packages/django/core/handlers/base.py", line 147, in get_response
    response = wrapped_callback(request, *callback_args, **callback_kwargs)
  File "/home/pi/django/blog/views.py", line 34, in post_edit
    post.author = reqquest.user
NameError: name 'reqquest' is not defined
[14/Jun/2016 11:51:30] "POST /post/2/edit/ HTTP/1.1" 500 61023
Performing system checks...

System check identified no issues (0 silenced).
June 14, 2016 - 11:36:17
Django version 1.9.6, using settings 'mysite.settings'
Starting development server at http://192.168.0.108:8000/
Quit the server with CONTROL-C.
/home/pi/django/myvenv/lib/python3.4/site-packages/django/shortcuts.py:204: RemovedInDjango110Warning: Reversing by dotted path is deprecated (blog.views.post_detail).
  return urlresolvers.reverse(to, args=args, kwargs=kwargs)

[14/Jun/2016 11:51:58] "POST /post/2/edit/ HTTP/1.1" 302 0
[14/Jun/2016 11:51:58] "GET /post/2/ HTTP/1.1" 200 1191
[14/Jun/2016 15:34:53] "GET /post/2/ HTTP/1.1" 200 1286
[14/Jun/2016 15:34:58] "GET /static/css/blog.css HTTP/1.1" 304 0
[14/Jun/2016 15:34:59] "GET / HTTP/1.1" 200 1971
[14/Jun/2016 15:35:06] "GET /post/new/ HTTP/1.1" 200 1415
[14/Jun/2016 15:35:07] "GET /post/new/ HTTP/1.1" 200 1415
[14/Jun/2016 15:36:19] "GET / HTTP/1.1" 200 1878
[14/Jun/2016 15:36:21] "GET /post/new/ HTTP/1.1" 200 1322
[14/Jun/2016 15:36:32] "GET / HTTP/1.1" 200 1782
[14/Jun/2016 15:36:32] "GET /static/css/blog.css HTTP/1.1" 200 812
[14/Jun/2016 15:36:39] "GET /post/new HTTP/1.1" 301 0
[14/Jun/2016 15:36:39] "GET /post/new/ HTTP/1.1" 200 1226
[14/Jun/2016 15:36:39] "GET /static/css/blog.css HTTP/1.1" 304 0
Internal Server Error: /post/new/
Traceback (most recent call last):
  File "/home/pi/django/myvenv/lib/python3.4/site-packages/django/core/handlers/base.py", line 149, in get_response
    response = self.process_exception_by_middleware(e, request)
  File "/home/pi/django/myvenv/lib/python3.4/site-packages/django/core/handlers/base.py", line 147, in get_response
    response = wrapped_callback(request, *callback_args, **callback_kwargs)
  File "/home/pi/django/blog/views.py", line 20, in post_new
    post.author = request.user
  File "/home/pi/django/myvenv/lib/python3.4/site-packages/django/db/models/fields/related_descriptors.py", line 207, in __set__
    self.field.remote_field.model._meta.object_name,
ValueError: Cannot assign "<SimpleLazyObject: <django.contrib.auth.models.AnonymousUser object at 0x7479e290>>": "Post.author" must be a "User" instance.
